Workbook

Sheet sample-sales
A1: order_id | B1: date | C1: product | D1: quantity | E1: unit_price | F1: total | G1: region | H1: salesperson
A2: SO-1001 | B2: 46146 | C2: Mechanical Keyboard | D2: 6 | E2: 112.7 | F2: 676.2 | G2: North | H2: Sofia Kowalski
A3: SO-1002 | B3: 46199 | C3: USB-C Hub | D3: 6 | E3: 35.78 | F3: 214.68 | G3: South | H3: Sofia Kowalski
A4: SO-1003 | B4: 46089 | C4: Standing Desk | D4: 1 | E4: 111.15 | F4: 111.15 | G4: South | H4: Elena Cohen
A5: SO-1004 | B5: 46067 | C5: Webcam 1080p | D5: 1 | E5: 112.67 | F5: 112.67 | G5: East | H5: Omar Haddad
A6: SO-1005 | B6: 46075 | C6: Webcam 1080p | D6: 1 | E6: 54.09 | F6: 54.09 | G6: Central | H6: Sofia Kowalski
A7: SO-1006 | B7: 46040 | C7: Desk Lamp | D7: 4 | E7: 215.54 | F7: 862.16 | G7: West | H7: Omar Haddad
A8: SO-1007 | B8: 46125 | C8: Cable Organizer | D8: 3 | E8: 17.52 | F8: 52.56 | G8: East | H8: Tomás Tanaka
A9: SO-1008 | B9: 46148 | C9: Noise-Cancelling Headphones | D9: 6 | E9: 181.65 | F9: 1089.9 | G9: West | H9: Omar Haddad
A10: SO-1009 | B10: 46116 | C10: Laptop Stand | D10: 8 | E10: 28.72 | F10: 229.76 | G10: East | H10: Sofia Kowalski
A11: SO-1010 | B11: 46082 | C11: Ergonomic Chair | D11: 7 | E11: 143.97 | F11: 1007.79 | G11: East | H11: Priya Herrera
A12: SO-1011 | B12: 46049 | C12: Cable Organizer | D12: 7 | E12: 147.79 | F12: 1034.53 | G12: North | H12: Priya Herrera
A13: SO-1012 | B13: 46161 | C13: Wireless Mouse | D13: 5 | E13: 206.67 | F13: 1033.35 | G13: North | H13: Chen Bennett
... A241: SO-1240 | B241: 46116 | C241: Webcam 1080p | D241: 6 | E241: 160.47 | F241: 962.82 | G241: Central | H241: Chen Bennett

Sheet sales_data
A1: order_id | B1: date | C1: product | D1: quantity | E1: unit_price | F1: total | G1: region | H1: salesperson
A2: SO-1001 | B2: 46146 | C2: Mechanical Keyboard | D2: 6 | E2: 112.7 | F2: 676.2 | G2: North | H2: Sofia Kowalski
A3: SO-1002 | B3: 46199 | C3: USB-C Hub | D3: 6 | E3: 35.78 | F3: 214.68 | G3: South | H3: Sofia Kowalski
A4: SO-1003 | B4: 46089 | C4: Standing Desk | D4: 1 | E4: 111.15 | F4: 111.15 | G4: South | H4: Elena Cohen
A5: SO-1004 | B5: 46067 | C5: Webcam 1080p | D5: 1 | E5: 112.67 | F5: 112.67 | G5: East | H5: Omar Haddad
A6: SO-1005 | B6: 46075 | C6: Webcam 1080p | D6: 1 | E6: 54.09 | F6: 54.09 | G6: Central | H6: Sofia Kowalski
A7: SO-1006 | B7: 46040 | C7: Desk Lamp | D7: 4 | E7: 215.54 | F7: 862.16 | G7: West | H7: Omar Haddad
A8: SO-1007 | B8: 46125 | C8: Cable Organizer | D8: 3 | E8: 17.52 | F8: 52.56 | G8: East | H8: Tomás Tanaka
A9: SO-1008 | B9: 46148 | C9: Noise-Cancelling Headphones | D9: 6 | E9: 181.65 | F9: 1089.9 | G9: West | H9: Omar Haddad
A10: SO-1009 | B10: 46116 | C10: Laptop Stand | D10: 8 | E10: 28.72 | F10: 229.76 | G10: East | H10: Sofia Kowalski
A11: SO-1010 | B11: 46082 | C11: Ergonomic Chair | D11: 7 | E11: 143.97 | F11: 1007.79 | G11: East | H11: Priya Herrera
A12: SO-1011 | B12: 46049 | C12: Cable Organizer | D12: 7 | E12: 147.79 | F12: 1034.53 | G12: North | H12: Priya Herrera
A13: SO-1012 | B13: 46161 | C13: Wireless Mouse | D13: 5 | E13: 206.67 | F13: 1033.35 | G13: North | H13: Chen Bennett
... A241: SO-1240 | B241: 46116 | C241: Webcam 1080p | D241: 6 | E241: 160.47 | F241: 962.82 | G241: Central | H241: Chen Bennett

Sheet Analysis
A1: Business Sales Performances Analysis
A3: Total Revenue | B3: =SUM(sales_data!F2:F1000) -> 142437.14
A4: Total Quality Sold | B4: =SUM(sales_data!F3:F1000) -> 141760.94
A5: Number of Orders | B5: =SUM(sales_data!F4:F1000) -> 141546.26
A7: Revenue by Region
A8: Region | B8: Revenue
A9: North | B9: =SUMIF(sales_data!G:G,A9,sales_data!F:F) -> 28925
A10: South | B10: =SUMIF(sales_data!G:G,A10,sales_data!F:F) -> 30083.51
A11: East | B11: =SUMIF(sales_data!G:G,A11,sales_data!F:F) -> 26485.82
A12: West | B12: =SUMIF(sales_data!G:G,A12,sales_data!F:F) -> 26154.87
A14: Top_Selling Products
A15: Product | B15: Quantity Sold
A16: {=UNIQUE(sales_data!C2:C1000)} -> Mechanical Keyboard | B16: =SUMIF(sales_data!$C$2:$C$241,A16,sales_data!$D$2:$D$241) -> 75
A17: USB-C Hub | B17: =SUMIF(sales_data!$C$2:$C$241,A17,sales_data!$D$2:$D$241) -> 77
A18: Standing Desk | B18: =SUMIF(sales_data!$C$2:$C$241,A18,sales_data!$D$2:$D$241) -> 65
A19: Webcam 1080p | B19: =SUMIF(sales_data!$C$2:$C$241,A19,sales_data!$D$2:$D$241) -> 122
A20: Desk Lamp | B20: =SUMIF(sales_data!$C$2:$C$241,A20,sales_data!$D$2:$D$241) -> 71
A21: Cable Organizer | B21: =SUMIF(sales_data!$C$2:$C$241,A21,sales_data!$D$2:$D$241) -> 113
A22: Noise-Cancelling Headphones | B22: =SUMIF(sales_data!$C$2:$C$241,A22,sales_data!$D$2:$D$241) -> 79
A23: Laptop Stand | B23: =SUMIF(sales_data!$C$2:$C$241,A23,sales_data!$D$2:$D$241) -> 133
A24: Ergonomic Chair | B24: =SUMIF(sales_data!$C$2:$C$241,A24,sales_data!$D$2:$D$241) -> 98
A25: Wireless Mouse | B25: =SUMIF(sales_data!$C$2:$C$241,A25,sales_data!$D$2:$D$241) -> 102
A26: External SSD 1TB | B26: =SUMIF(sales_data!$C$2:$C$241,A26,sales_data!$D$2:$D$241) -> 97
A27: 27-inch Monitor | B27: =SUMIF(sales_data!$C$2:$C$241,A27,sales_data!$D$2:$D$241) -> 76
A30: Monthly Revenue Trend
A31: Month | B31: Revenue
A32: January | B32: =SUMIFS(sales_data!F:F,sales_data!B:B,">="&DATE(2026,1,1),sales_data!B:B,"<"&DATE(2026,2,1)) -> 24177.45
A33: February | B33: =SUMIF(sales_data!B:B,">="&DATE(2026,2,1),sales_data!F:F)-SUMIF(sales_data!B:B,">="&DATE(2026,3,1),sales_data!F:F) -> 13788.89
A34: March | B34: =SUMIF(sales_data!B:B,">="&DATE(2026,3,1),sales_data!F:F)-SUMIF(sales_data!B:B,">="&DATE(2026,4,1),sales_data!F:F) -> 19390.28
A35: April | B35: =SUMIF(sales_data!B:B,">="&DATE(2026,4,1),sales_data!F:F)-SUMIF(sales_data!B:B,">="&DATE(2026,5,1),sales_data!F:F) -> 23471.38
A36: May | B36: =SUMIF(sales_data!B:B,">="&DATE(2026,5,1),sales_data!F:F)-SUMIF(sales_data!B:B,">="&DATE(2026,6,1),sales_data!F:F) -> 24885.97
A37: June | B37: =SUMIF(sales_data!B:B,">="&DATE(2026,6,1),sales_data!F:F)-SUMIF(sales_data!B:B,">="&DATE(2026,7,1),sales_data!F:F) -> 36723.17
A38: July | B38: =SUMIF(sales_data!B:B,">="&DATE(2026,7,1),sales_data!F:F)-SUMIF(sales_data!B:B,">="&DATE(2026,8,1),sales_data!F:F) -> 0
A39: August | B39: =SUMIF(sales_data!B:B,">="&DATE(2026,8,1),sales_data!F:F)-SUMIF(sales_data!B:B,">="&DATE(2026,9,1),sales_data!F:F) -> 0
A40: September | B40: =SUMIF(sales_data!B:B,">="&DATE(2026,9,1),sales_data!F:F)-SUMIF(sales_data!B:B,">="&DATE(2026,10,1),sales_data!F:F) -> 0
A41: October | B41: =SUMIF(sales_data!B:B,">="&DATE(2026,10,1),sales_data!F:F)-SUMIF(sales_data!B:B,">="&DATE(2026,11,1),sales_data!F:F) -> 0
A42: November | B42: =SUMIF(sales_data!B:B,">="&DATE(2026,11,1),sales_data!F:F)-SUMIF(sales_data!B:B,">="&DATE(2026,12,1),sales_data!F:F) -> 0
A43: December | B43: =SUMIF(sales_data!B:B,">="&DATE(2026,12,1),sales_data!F:F)-SUMIF(sales_data!B:B,">="&DATE(2026,13,1),sales_data!F:F) -> 0
A45: Key Business Insights
A46: 1.Total Revenue and Sales Valume were analyzed to understand overall business performance
...
